Workbook

Sheet SALES BY MONTH
A3: Sum of Final Price | B3: Sales Rep
A4: Month | B4: Adity Rao | C4: Aman Shah | D4: Amol Sharma | E4: Komal Sharma | F4: Neha Singh | G4: Priya Mehta | H4: Rajesh Nair | I4: Rohit Kholi | J4: Grand Total
A5: Jan | B5: 6525.5 | C5: 5657 | D5: 13947 | E5: 14834 | F5: 6470 | G5: 3875 | H5: 5012.5 | I5: 8235 | J5: 64556
A6: Feb | B6: 4943 | C6: 8755.5 | D6: 7843.5 | E6: 7438 | F6: 13056 | G6: 9048 | H6: 6616.8 | I6: 3022 | J6: 60722.8
A7: Mar | B7: 6442 | C7: 6577 | D7: 12988 | E7: 11751 | F7: 3746 | G7: 2926 | H7: 4172 | I7: 9500 | J7: 58102
A8: Apr | B8: 9030 | C8: 5228 | D8: 17053.5 | E8: 7975 | F8: 9817.5 | G8: 5662 | H8: 5015 | I8: 3450 | J8: 63231
A9: May | B9: 4016 | C9: 6316 | D9: 4050 | E9: 7629.8 | F9: 9943.5 | G9: 11786.25 | H9: 11613.25 | I9: 7233 | J9: 62587.8
A10: Jun | B10: 7895 | C10: 5394 | D10: 4936 | E10: 4693 | F10: 4092 | G10: 5953.2 | H10: 12975 | I10: 10070.05 | J10: 56008.25
A11: Jul | B11: 6070 | C11: 4771 | D11: 8658 | E11: 10984 | F11: 14492.25 | G11: 3897.25 | H11: 6644.8 | I11: 5013 | J11: 60530.3
A12: Aug | B12: 2985 | C12: 15561 | D12: 6714 | E12: 4006 | F12: 3925 | G12: 8700 | H12: 14153 | I12: 3980 | J12: 60024
A13: Sep | B13: 9504 | C13: 5134 | D13: 6602 | E13: 6626.25 | F13: 5785.5 | G13: 8358 | H13: 8851 | I13: 10075 | J13: 60935.75
A14: Oct | B14: 9261 | C14: 6381.2 | D14: 9530 | E14: 9954 | F14: 11349 | G14: 4714 | H14: 12394 | I14: 4999 | J14: 68582.2
A15: Nov | B15: 4322.8 | C15: 8418 | D15: 7762.2 | E15: 6205 | F15: 6922.25 | G15: 13165 | H15: 9373.25 | I15: 6735 | J15: 62903.5
A16: Dec | B16: 12000 | C16: 9457.45 | D16: 3516 | E16: 4826 | F16: 4926 | G16: 5780 | H16: 20401 | I16: 6396 | J16: 67302.45
A17: Grand Total | B17: 82994.3 | C17: 87650.15 | D17: 103600.2 | E17: 96922.05 | F17: 94525 | G17: 83864.7 | H17: 117221.6 | I17: 78708.05 | J17: 745486.05

Sheet SALES DATA
A1: Medicare Pharma Distributors Pvt. Ltd.
A3: Invoice No | B3: Date | C3: Month | D3: Sales Rep | E3: Region | F3: Customer ID | G3: Company Name | H3: Company Representative Name | I3: Products | J3: Batch No | K3: Expiry | L3: Qty | M3: Price/Unit | N3: Total | O3: Discount | P3: Final Price
A4: 101 | B4: 45384 | C4: =TEXT(B4,"mmm") -> Apr | D4: Rajesh Nair | E4: North | F4: C101 | G4: =VLOOKUP(F4,'CUSTOMER INFO'!B3:D10,2,FALSE) -> Shree Medical & General Store | H4: =VLOOKUP(F4,'CUSTOMER INFO'!B3:D10,3,FALSE) -> Abhijeet Kulkarni | I4: Paracetamol 650mg | J4: B23P650 | K4: 46357 | L4: 50 | M4: 18 | N4: =L4*M4 -> 900 | O4: =IF(L4>=60,"Y","N") -> N | P4: =IF(L4>=60,0.95*N4,N4) -> 900
A5: 102 | B5: 45384 | C5: =TEXT(B5,"mmm") -> Apr | D5: Neha Singh | E5: West | F5: C132 | G5: =VLOOKUP(F5,'CUSTOMER INFO'!B4:D11,2,FALSE) -> JeevanCare Medical Store | H5: =VLOOKUP(F5,'CUSTOMER INFO'!B4:D11,3,FALSE) -> Neha Patel | I5: Cough Syrup 100ml | J5: B19CS01 | K5: 46235 | L5: 30 | M5: 75 | N5: =L5*M5 -> 2250 | O5: =IF(L5>=60,"Y","N") -> N | P5: =IF(L5>=60,0.95*N5,N5) -> 2250
A6: 103 | B6: 45385 | C6: =TEXT(B6,"mmm") -> Apr | D6: Adity Rao | E6: South | F6: C140 | G6: =VLOOKUP(F6,'CUSTOMER INFO'!B5:D12,2,FALSE) -> Arogya Medical & General | H6: =VLOOKUP(F6,'CUSTOMER INFO'!B5:D12,3,FALSE) -> Hrishkesh Jadhv | I6: Vitamin C Tablets | J6: B22VC10 | K6: 45870 | L6: 40 | M6: 55 | N6: =L6*M6 -> 2200 | O6: =IF(L6>=60,"Y","N") -> N | P6: =IF(L6>=60,0.95*N6,N6) -> 2200
A7: 104 | B7: 45386 | C7: =TEXT(B7,"mmm") -> Apr | D7: Priya Mehta | E7: East | F7: C150 | G7: =VLOOKUP(F7,'CUSTOMER INFO'!B6:D13,2,FALSE) -> MedEase | H7: =VLOOKUP(F7,'CUSTOMER INFO'!B6:D13,3,FALSE) -> Siddant Patil | I7: Amoxicillin 500mg | J7: B21AX50 | K7: 46266 | L7: 35 | M7: 32 | N7: =L7*M7 -> 1120 | O7: =IF(L7>=60,"Y","N") -> N | P7: =IF(L7>=60,0.95*N7,N7) -> 1120
A8: 105 | B8: 45387 | C8: =TEXT(B8,"mmm") -> Apr | D8: Amol Sharma | E8: North | F8: C157 | G8: =VLOOKUP(F8,'CUSTOMER INFO'!B7:D14,2,FALSE) -> CityMed Pharmacy | H8: =VLOOKUP(F8,'CUSTOMER INFO'!B7:D14,3,FALSE) -> Vikram Shah | I8: Hand Sanitizer 200ml | J8: B20HS20 | K8: 46357 | L8: 60 | M8: 90 | N8: =L8*M8 -> 5400 | O8: =IF(L8>=60,"Y","N") -> Y | P8: =IF(L8>=60,0.95*N8,N8) -> 5130
A9: 106 | B9: 45388 | C9: =TEXT(B9,"mmm") -> Apr | D9: Rohit Kholi | E9: West | F9: C201 | G9: =VLOOKUP(F9,'CUSTOMER INFO'!B8:D15,2,FALSE) -> TrustCare Medicals | H9: =VLOOKUP(F9,'CUSTOMER INFO'!B8:D15,3,FALSE) -> Pooja Sharma | I9: ORS Powder | J9: B23OR01 | K9: 46296 | L9: 55 | M9: 20 | N9: =L9*M9 -> 1100 | O9: =IF(L9>=60,"Y","N") -> N | P9: =IF(L9>=60,0.95*N9,N9) -> 1100
A10: 107 | B10: 45389 | C10: =TEXT(B10,"mmm") -> Apr | D10: Aman Shah | E10: South | F10: C245 | G10: =VLOOKUP(F10,'CUSTOMER INFO'!B9:D16,2,FALSE) -> Lifeline Medicals | H10: =VLOOKUP(F10,'CUSTOMER INFO'!B9:D16,3,FALSE) -> Harshal Singh | I10: Zinc Tablets | J10: B22ZC05 | K10: 46083 | L10: 25 | M10: 35 | N10: =L10*M10 -> 875 | O10: =IF(L10>=60,"Y","N") -> N | P10: =IF(L10>=60,0.95*N10,N10) -> 875
A11: 108 | B11: 45390 | C11: =TEXT(B11,"mmm") -> Apr | D11: Komal Sharma | E11: East | F11: C160 | G11: =VLOOKUP(F11,'CUSTOMER INFO'!B10:D17,2,FALSE) -> CarePlus Medical Store | H11: =VLOOKUP(F11,'CUSTOMER INFO'!B10:D17,3,FALSE) -> Riya Mishra | I11: Vitamin D3 60k | J11: B21VD60 | K11: 46381 | L11: 35 | M11: 42 | N11: =L11*M11 -> 1470 | O11: =IF(L11>=60,"Y","N") -> N | P11: =IF(L11>=60,0.95*N11,N11) -> 1470
A12: 109 | B12: 45391 | C12: =TEXT(B12,"mmm") -> Apr | D12: Rajesh Nair | E12: North | F12: C101 | G12: =VLOOKUP(F12,'CUSTOMER INFO'!B3:D10,2,FALSE) -> Shree Medical & General Store | H12: =VLOOKUP(F12,'CUSTOMER INFO'!B3:D10,3,FALSE) -> Abhijeet Kulkarni | I12: Antacid Tablets | J12: B21AC04 | K12: 46115 | L12: 45 | M12: 22 | N12: =L12*M12 -> 990 | O12: =IF(L12>=60,"Y","N") -> N | P12: =IF(L12>=60,0.95*N12,N12) -> 990
A13: 110 | B13: 45392 | C13: =TEXT(B13,"mmm") -> Apr | D13: Neha Singh | E13: West | F13: C132 | G13: =VLOOKUP(F13,'CUSTOMER INFO'!B4:D11,2,FALSE) -> JeevanCare Medical Store | H13: =VLOOKUP(F13,'CUSTOMER INFO'!B4:D11,3,FALSE) -> Neha Patel | I13: Ciprofloxacin 500mg | J13: B23CF50 | K13: 46178 | L13: 38 | M13: 48 | N13: =L13*M13 -> 1824 | O13: =IF(L13>=60,"Y","N") -> N | P13: =IF(L13>=60,0.95*N13,N13) -> 1824
A14: 111 | B14: 45393 | C14: =TEXT(B14,"mmm") -> Apr | D14: Adity Rao | E14: South | F14: C140 | G14: =VLOOKUP(F14,'CUSTOMER INFO'!B5:D12,2,FALSE) -> Arogya Medical & General | H14: =VLOOKUP(F14,'CUSTOMER INFO'!B5:D12,3,FALSE) -> Hrishkesh Jadhv | I14: Antibiotic Ointment | J14: B23AO10 | K14: 46297 | L14: 52 | M14: 95 | N14: =L14*M14 -> 4940 | O14: =IF(L14>=60,"Y","N") -> N | P14: =IF(L14>=60,0.95*N14,N14) -> 4940
A15: 112 | B15: 45394 | C15: =TEXT(B15,"mmm") -> Apr | D15: Priya Mehta | E15: East | F15: C150 | G15: =VLOOKUP(F15,'CUSTOMER INFO'!B6:D13,2,FALSE) -> MedEase | H15: =VLOOKUP(F15,'CUSTOMER INFO'!B6:D13,3,FALSE) -> Siddant Patil | I15: Paracetamol 650mg | J15: B23P651 | K15: 46357 | L15: 54 | M15: 18 | N15: =L15*M15 -> 972 | O15: =IF(L15>=60,"Y","N") -> N | P15: =IF(L15>=60,0.95*N15,N15) -> 972
A16: 113 | B16: 45395 | C16: =TEXT(B16,"mmm") -> Apr | D16: Amol Sharma | E16: North | F16: C157 | G16: =VLOOKUP(F16,'CUSTOMER INFO'!B7:D14,2,FALSE) -> CityMed Pharmacy | H16: =VLOOKUP(F16,'CUSTOMER INFO'!B7:D14,3,FALSE) -> Vikram Shah | I16: Cough Syrup 100ml | J16: B19CS02 | K16: 46235 | L16: 56 | M16: 75 | N16: =L16*M16 -> 4200 | O16: =IF(L16>=60,"Y","N") -> N | P16: =IF(L16>=60,0.95*N16,N16) -> 4200
A17: 114 | B17: 45396 | C17: =TEXT(B17,"mmm") -> Apr | D17: Rohit Kholi | E17: West | F17: C201 | G17: =VLOOKUP(F17,'CUSTOMER INFO'!B8:D15,2,FALSE) -> TrustCare Medicals | H17: =VLOOKUP(F17,'CUSTOMER INFO'!B8:D15,3,FALSE) -> Pooja Sharma | I17: Vitamin C Tablets | J17: B22VC11 | K17: 45870 | L17: 28 | M17: 55 | N17: =L17*M17 -> 1540 | O17: =IF(L17>=60,"Y","N") -> N | P17: =IF(L17>=60,0.95*N17,N17) -> 1540
A18: 115 | B18: 45397 | C18: =TEXT(B18,"mmm") -> Apr | D18: Aman Shah | E18: North | F18: C245 | G18: =VLOOKUP(F18,'CUSTOMER INFO'!B9:D16,2,FALSE) -> Lifeline Medicals | H18: =VLOOKUP(F18,'CUSTOMER INFO'!B9:D16,3,FALSE) -> Harshal Singh | I18: Amoxicillin 500mg | J18: B21AX51 | K18: 46266 | L18: 54 | M18: 32 | N18: =L18*M18 -> 1728 | O18: =IF(L18>=60,"Y","N") -> N | P18: =IF(L18>=60,0.95*N18,N18) -> 1728
A19: 116 | B19: 45398 | C19: =TEXT(B19,"mmm") -> Apr | D19: Komal Sharma | E19: West | F19: C160 | G19: =VLOOKUP(F19,'CUSTOMER INFO'!B10:D17,2,FALSE) -> CarePlus Medical Store | H19: =VLOOKUP(F19,'CUSTOMER INFO'!B10:D17,3,FALSE) -> Riya Mishra | I19: Hand Sanitizer 200ml | J19: B20HS21 | K19: 46357 | L19: 60 | M19: 90 | N19: =L19*M19 -> 5400 | O19: =IF(L19>=60,"Y","N") -> Y | P19: =IF(L19>=60,0.95*N19,N19) -> 5130
A20: 117 | B20: 45399 | C20: =TEXT(B20,"mmm") -> Apr | D20: Rajesh Nair | E20: South | F20: C101 | G20: =VLOOKUP(F20,'CUSTOMER INFO'!B3:D10,2,FALSE) -> Shree Medical & General Store | H20: =VLOOKUP(Table1[[#This Row],[Customer ID]],'CUSTOMER INFO'!B3:D10,3,FALSE) -> Abhijeet Kulkarni | I20: ORS Powder | J20: B23OR02 | K20: 46296 | L20: 55 | M20: 20 | N20: =L20*M20 -> 1100 | O20: =IF(L20>=60,"Y","N") -> N | P20: =IF(L20>=60,0.95*N20,N20) -> 1100
A21: 118 | B21: 45400 | C21: =TEXT(B21,"mmm") -> Apr | D21: Rajesh Nair | E21: East | F21: C132 | G21: =VLOOKUP(F21,'CUSTOMER INFO'!B4:D11,2,FALSE) -> JeevanCare Medical Store | H21: =VLOOKUP(Table1[[#This Row],[Customer ID]],'CUSTOMER INFO'!B4:D11,3,FALSE) -> Neha Patel | I21: Zinc Tablets | J21: B22ZC06 | K21: 46083 | L21: 35 | M21: 35 | N21: =L21*M21 -> 1225 | O21: =IF(L21>=60,"Y","N") -> N | P21: =IF(L21>=60,0.95*N21,N21) -> 1225
A22: 119 | B22: 45401 | C22: =TEXT(B22,"mmm") -> Apr | D22: Neha Singh | E22: North | F22: C140 | G22: =VLOOKUP(F22,'CUSTOMER INFO'!B5:D12,2,FALSE) -> Arogya Medical & General | H22: =VLOOKUP(Table1[[#This Row],[Customer ID]],'CUSTOMER INFO'!B5:D12,3,FALSE) -> Hrishkesh Jadhv | I22: Paracetamol 650mg | J22: B23P651 | K22: 46381 | L22: 65 | M22: 42 | N22: =L22*M22 -> 2730 | O22: =IF(L22>=60,"Y","N") -> Y | P22: =IF(L22>=60,0.95*N22,N22) -> 2593.5
A23: 120 | B23: 45402 | C23: =TEXT(B23,"mmm") -> Apr | D23: Adity Rao | E23: West | F23: C150 | G23: =VLOOKUP(F23,'CUSTOMER INFO'!B6:D13,2,FALSE) -> MedEase | H23: =VLOOKUP(Table1[[#This Row],[Customer ID]],'CUSTOMER INFO'!B6:D13,3,FALSE) -> Siddant Patil | I23: Cough Syrup 100ml | J23: B19CS02 | K23: 46115 | L23: 45 | M23: 22 | N23: =L23*M23 -> 990 | O23: =IF(L23>=60,"Y","N") -> N | P23: =IF(L23>=60,0.95*N23,N23) -> 990
A24: 121 | B24: 45403 | C24: =TEXT(B24,"mmm") -> Apr | D24: Priya Mehta | E24: South | F24: C157 | G24: =VLOOKUP(F24,'CUSTOMER INFO'!B7:D14,2,FALSE) -> CityMed Pharmacy | H24: =VLOOKUP(Table1[[#This Row],[Customer ID]],'CUSTOMER INFO'!B7:D14,3,FALSE) -> Vikram Shah | I24: Vitamin C Tablets | J24: B22VC11 | K24: 46178 | L24: 35 | M24: 48 | N24: =L24*M24 -> 1680 | O24: =IF(L24>=60,"Y","N") -> N | P24: =IF(L24>=60,0.95*N24,N24) -> 1680
A25: 122 | B25: 45404 | C25: =TEXT(B25,"mmm") -> Apr | D25: Amol Sharma | E25: East | F25: C201 | G25: =VLOOKUP(F25,'CUSTOMER INFO'!B8:D15,2,FALSE) -> TrustCare Medicals | H25: =VLOOKUP(Table1[[#This Row],[Customer ID]],'CUSTOMER INFO'!B8:D15,3,FALSE) -> Pooja Sharma | I25: Amoxicillin 500mg | J25: B21AX51 | K25: 46297 | L25: 54 | M25: 95 | N25: =L25*M25 -> 5130 | O25: =IF(L25>=60,"Y","N") -> N | P25: =IF(L25>=60,0.95*N25,N25) -> 5130
A26: 123 | B26: 45405 | C26: =TEXT(B26,"mmm") -> Apr | D26: Rohit Kholi | E26: North | F26: C245 | G26: =VLOOKUP(F26,'CUSTOMER INFO'!B9:D16,2,FALSE) -> Lifeline Medicals | H26: =VLOOKUP(Table1[[#This Row],[Customer ID]],'CUSTOMER INFO'!B9:D16,3,FALSE) -> Harshal Singh | I26: Hand Sanitizer 200ml | J26: B20HS21 | K26: 46357 | L26: 45 | M26: 18 | N26: =L26*M26 -> 810 | O26: =IF(L26>=60,"Y","N") -> N | P26: =IF(L26>=60,0.95*N26,N26) -> 810
A27: 124 | B27: 45406 | C27: =TEXT(B27,"mmm") -> Apr | D27: Aman Shah | E27: West | F27: C160 | G27: =VLOOKUP(F27,'CUSTOMER INFO'!B10:D17,2,FALSE) -> CarePlus Medical Store | H27: =VLOOKUP(Table1[[#This Row],[Customer ID]],'CUSTOMER INFO'!B10:D17,3,FALSE) -> Riya Mishra | I27: ORS Powder | J27: B23OR02 | K27: 46235 | L27: 35 | M27: 75 | N27: =L27*M27 -> 2625 | O27: =IF(L27>=60,"Y","N") -> N | P27: =IF(L27>=60,0.95*N27,N27) -> 2625
A28: 125 | B28: 45407 | C28: =TEXT(B28,"mmm") -> Apr | D28: Komal Sharma | E28: South | F28: C101 | G28: =VLOOKUP(F28,'CUSTOMER INFO'!B3:D10,2,FALSE) -> Shree Medical & General Store | H28: =VLOOKUP(Table1[[#This Row],[Customer ID]],'CUSTOMER INFO'!B3:D10,3,FALSE) -> Abhijeet Kulkarni | I28: Zinc Tablets | J28: B22ZC06 | K28: 45870 | L28: 25 | M28: 55 | N28: =L28*M28 -> 1375 | O28: =IF(L28>=60,"Y","N") -> N | P28: =IF(L28>=60,0.95*N28,N28) -> 1375
A29: 126 | B29: 45408 | C29: =TEXT(B29,"mmm") -> Apr | D29: Rajesh Nair | E29: East | F29: C132 | G29: =VLOOKUP(F29,'CUSTOMER INFO'!B4:D11,2,FALSE) -> JeevanCare Medical Store | H29: =VLOOKUP(Table1[[#This Row],[Customer ID]],'CUSTOMER INFO'!B4:D11,3,FALSE) -> Neha Patel | I29: Vitamin D3 60k | J29: B21VD61 | K29: 46266 | L29: 25 | M29: 32 | N29: =L29*M29 -> 800 | O29: =IF(L29>=60,"Y","N") -> N | P29: =IF(L29>=60,0.95*N29,N29) -> 800
A30: 127 | B30: 45409 | C30: =TEXT(B30,"mmm") -> Apr | D30: Neha Singh | E30: North | F30: C140 | G30: =VLOOKUP(F30,'CUSTOMER INFO'!B5:D12,2,FALSE) -> Arogya Medical & General | H30: =VLOOKUP(Table1[[#This Row],[Customer ID]],'CUSTOMER INFO'!B5:D12,3,FALSE) -> Hrishkesh Jadhv | I30: Antacid Tablets | J30: B21AC05 | K30: 46357 | L30: 35 | M30: 90 | N30: =L30*M30 -> 3150 | O30: =IF(L30>=60,"Y","N") -> N | P30: =IF(L30>=60,0.95*N30,N30) -> 3150
A31: 128 | B31: 45410 | C31: =TEXT(B31,"mmm") -> Apr | D31: Adity Rao | E31: West | F31: C150 | G31: =VLOOKUP(F31,'CUSTOMER INFO'!B6:D13,2,FALSE) -> MedEase | H31: =VLOOKUP(Table1[[#This Row],[Customer ID]],'CUSTOMER INFO'!B6:D13,3,FALSE) -> Siddant Patil | I31: Ciprofloxacin 500mg | J31: B23CF51 | K31: 46296 | L31: 45 | M31: 20 | N31: =L31*M31 -> 900 | O31: =IF(L31>=60,"Y","N") -> N | P31: =IF(L31>=60,0.95*N31,N31) -> 900
A32: 129 | B32: 45411 | C32: =TEXT(B32,"mmm") -> Apr | D32: Priya Mehta | E32: North | F32: C157 | G32: =VLOOKUP(F32,'CUSTOMER INFO'!B7:D14,2,FALSE) -> CityMed Pharmacy | H32: =VLOOKUP(Table1[[#This Row],[Customer ID]],'CUSTOMER INFO'!B7:D14,3,FALSE) -> Vikram Shah | I32: Antibiotic Ointment | J32: B23AO11 | K32: 46083 | L32: 54 | M32: 35 | N32: =L32*M32 -> 1890 | O32: =IF(L32>=60,"Y","N") -> N | P32: =IF(L32>=60,0.95*N32,N32) -> 1890
A33: 130 | B33: 45412 | C33: =TEXT(B33,"mmm") -> Apr | D33: Amol Sharma | E33: West | F33: C201 | G33: =VLOOKUP(F33,'CUSTOMER INFO'!B8:D15,2,FALSE) -> TrustCare Medicals | H33: =VLOOKUP(Table1[[#This Row],[Customer ID]],'CUSTOMER INFO'!B8:D15,3,FALSE) -> Pooja Sharma | I33: Paracetamol 650mg | J33: B23P652 | K33: 46381 | L33: 65 | M33: 42 | N33: =L33*M33 -> 2730 | O33: =IF(L33>=60,"Y","N") -> Y | P33: =IF(L33>=60,0.95*N33,N33) -> 2593.5
A34: 131 | B34: 45413 | C34: =TEXT(B34,"mmm") -> May | D34: Rohit Kholi | E34: South | F34: C245 | G34: =VLOOKUP(F34,'CUSTOMER INFO'!B9:D16,2,FALSE) -> Lifeline Medicals | H34: =VLOOKUP(Table1[[#This Row],[Customer ID]],'CUSTOMER INFO'!B9:D16,3,FALSE) -> Harshal Singh | I34: Cough Syrup 100ml | J34: B19CS03 | K34: 46115 | L34: 45 | M34: 22 | N34: =L34*M34 -> 990 | O34: =IF(L34>=60,"Y","N") -> N | P34: =IF(L34>=60,0.95*N34,N34) -> 990
A35: 132 | B35: 45414 | C35: =TEXT(B35,"mmm") -> May | D35: Aman Shah | E35: East | F35: C160 | G35: =VLOOKUP(F35,'CUSTOMER INFO'!B10:D17,2,FALSE) -> CarePlus Medical Store | H35: =VLOOKUP(Table1[[#This Row],[Customer ID]],'CUSTOMER INFO'!B10:D17,3,FALSE) -> Riya Mishra | I35: Vitamin C Tablets | J35: B22VC12 | K35: 46178 | L35: 35 | M35: 48 | N35: =L35*M35 -> 1680 | O35: =IF(L35>=60,"Y","N") -> N | P35: =IF(L35>=60,0.95*N35,N35) -> 1680
A36: 133 | B36: 45415 | C36: =TEXT(B36,"mmm") -> May | D36: Komal Sharma | E36: North | F36: C101 | G36: =VLOOKUP(F36,'CUSTOMER INFO'!B3:D10,2,FALSE) -> Shree Medical & General Store | H36: =VLOOKUP(Table1[[#This Row],[Customer ID]],'CUSTOMER INFO'!B3:D10,3,FALSE) -> Abhijeet Kulkarni | I36: Amoxicillin 500mg | J36: B21AX52 | K36: 46297 | L36: 45 | M36: 95 | N36: =L36*M36 -> 4275 | O36: =IF(L36>=60,"Y","N") -> N | P36: =IF(L36>=60,0.95*N36,N36) -> 4275
A37: 134 | B37: 45416 | C37: =TEXT(B37,"mmm") -> May | D37: Rajesh Nair | E37: West | F37: C132 | G37: =VLOOKUP(F37,'CUSTOMER INFO'!B4:D11,2,FALSE) -> JeevanCare Medical Store | H37: =VLOOKUP(Table1[[#This Row],[Customer ID]],'CUSTOMER INFO'!B4:D11,3,FALSE) -> Neha Patel | I37: Hand Sanitizer 200ml | J37: B20HS22 | K37: 46357 | L37: 30 | M37: 18 | N37: =L37*M37 -> 540 | O37: =IF(L37>=60,"Y","N") -> N | P37: =IF(L37>=60,0.95*N37,N37) -> 540
A38: 135 | B38: 45417 | C38: =TEXT(B38,"mmm") -> May | D38: Rajesh Nair | E38: South | F38: C140 | G38: =VLOOKUP(F38,'CUSTOMER INFO'!B5:D12,2,FALSE) -> Arogya Medical & General | H38: =VLOOKUP(Table1[[#This Row],[Customer ID]],'CUSTOMER INFO'!B5:D12,3,FALSE) -> Hrishkesh Jadhv | I38: ORS Powder | J38: B23OR03 | K38: 46235 | L38: 65 | M38: 75 | N38: =L38*M38 -> 4875 | O38: =IF(L38>=60,"Y","N") -> Y | P38: =IF(L38>=60,0.95*N38,N38) -> 4631.25
A39: 136 | B39: 45418 | C39: =TEXT(B39,"mmm") -> May | D39: Neha Singh | E39: East | F39: C150 | G39: =VLOOKUP(F39,'CUSTOMER INFO'!B6:D13,2,FALSE) -> MedEase | H39: =VLOOKUP(Table1[[#This Row],[Customer ID]],'CUSTOMER INFO'!B6:D13,3,FALSE) -> Siddant Patil | I39: Zinc Tablets | J39: B22ZC07 | K39: 45870 | L39: 35 | M39: 55 | N39: =L39*M39 -> 1925 | O39: =IF(L39>=60,"Y","N") -> N | P39: =IF(L39>=60,0.95*N39,N39) -> 1925
A40: 137 | B40: 45419 | C40: =TEXT(B40,"mmm") -> May | D40: Adity Rao | E40: North | F40: C157 | G40: =VLOOKUP(F40,'CUSTOMER INFO'!B7:D14,2,FALSE) -> CityMed Pharmacy | H40: =VLOOKUP(Table1[[#This Row],[Customer ID]],'CUSTOMER INFO'!B7:D14,3,FALSE) -> Vikram Shah | I40: Paracetamol 650mg | J40: B23P652 | K40: 46266 | L40: 55 | M40: 32 | N40: =L40*M40 -> 1760 | O40: =IF(L40>=60,"Y","N") -> N | P40: =IF(L40>=60,0.95*N40,N40) -> 1760
A41: 138 | B41: 45420 | C41: =TEXT(B41,"mmm") -> May | D41: Priya Mehta | E41: West | F41: C201 | G41: =VLOOKUP(F41,'CUSTOMER INFO'!B8:D15,2,FALSE) -> TrustCare Medicals | H41: =VLOOKUP(Table1[[#This Row],[Customer ID]],'CUSTOMER INFO'!B8:D15,3,FALSE) -> Pooja Sharma | I41: Cough Syrup 100ml | J41: B19CS03 | K41: 46357 | L41: 32 | M41: 90 | N41: =L41*M41 -> 2880 | O41: =IF(L41>=60,"Y","N") -> N | P41: =IF(L41>=60,0.95*N41,N41) -> 2880
...

Sheet CUSTOMER INFO
B2: Customer ID | C2: Company | D2: Representative
B3: C101 | C3: Shree Medical & General Store | D3: Abhijeet Kulkarni
B4: C132 | C4: JeevanCare Medical Store | D4: Neha Patel
B5: C140 | C5: Arogya Medical & General | D5: Hrishkesh Jadhv
B6: C150 | C6: MedEase | D6: Siddant Patil
B7: C157 | C7: CityMed Pharmacy | D7: Vikram Shah
B8: C201 | C8: TrustCare Medicals | D8: Pooja Sharma
B9: C245 | C9: Lifeline Medicals | D9: Harshal Singh
B10: C160 | C10: CarePlus Medical Store | D10: Riya Mishra
G60: =VLOOKUP(F60,'CUSTOMER INFO'!B3:D10,2,FALSE) -> #N/A
G366: =VLOOKUP(F366,'CUSTOMER INFO'!B3:D10,2,FALSE) -> #N/A

Sheet ABOUT
A1: FIELD | B1: DETAILS
A2: AUTHOR | B2: RUTUJA SANTOSH SHANKPALE
A3: PROJECT TITLE | B3: GUIDED PROJECT: INTRODUCTION TO DATA ANALYSIS USING MICROSOFT EXCEL
A4: COURSE/SOURCE | B4: COURSERA
A5: INSTRUCTOR | B5: PAULA DEL REY
A6: CREATED ON | B6: 45990
A7: CONTACT | B7: www.linkedin.com/in/rutujashankpale
A8: COPYRIGHT | B8: © 2025 RUTUJA SHANKPALE. ORIGINAL WORK. ALL RIGHTS RESERVED.
